Workbook

Sheet 🏠 Portada
B2: CALCULADORA DE PRECIOS
B4: Herramienta para fijar el precio justo de tus servicios y productos
B6: DATOS DE TU NEGOCIO
B7: Nombre del negocio / freelancer | C7: Tu Nombre o Empresa
B8: Sector | C8: Ej: Consultoría, Formación, Ingeniería…
B9: Moneda | C9: EUR
B10: IVA general aplicable (%) | C10: 21
B11: Fecha de actualización | C11: 09/06/2026
B13: PESTAÑAS DISPONIBLES
B14: 👥 Equipo | C14: Define tu equipo, tarifas y capacidad facturable mensual.
B15: 📚 Formaciones | C15: Calcula el precio de cursos, talleres y formaciones.
B16: 🤝 Consultoría | C16: Proyectos de consultoría estratégica y asesoramiento.
B17: ⚙️ Ingeniería | C17: Proyectos técnicos, desarrollo e implementación.
B18: 📦 Producto | C18: Productos físicos o digitales con margen comercial.
B19: 📊 Resumen | C19: Comparativa de precios de todas las categorías.
B21: LEYENDA DE COLORES
B22: ■ Ejemplo | C22: Celda de entrada → Escribe tu dato aquí
B23: ■ Ejemplo | C23: Fórmula calculada → No modificar
B24: ■ Ejemplo | C24: Precio recomendado → Resultado final
B25: ■ Ejemplo | C25: Dato clave → Requiere revisión
B27: Fórmula: Precio = Coste Total + Margen + Prima de Valor

Sheet 👥 Equipo
B1: EQUIPO — CAPACIDAD Y COSTES
B4: Las horas facturables totales del equipo se usan automáticamente en todas las pestañas de servicio para prorratear los costes indirectos.
B6: Nombre / Rol | C6: Tipo | D6: Horas contratadas/mes | E6: % Tiempo facturable | F6: Horas facturables/mes | G6: Coste mensual (€)
C7: Propio/Colaborador | D7: h/mes | E7: % | F7: D × E | G7: €/mes
B8: Persona 1 | C8: Propio | D8: 160 | E8: 0.75 | F8: =D8*E8 -> 120 | G8: 0
B9: Persona 2 | C9: Propio | D9: 160 | E9: 0.75 | F9: =D9*E9 -> 120 | G9: 0
B10: Persona 3 | C10: Propio | D10: 160 | E10: 0.75 | F10: =D10*E10 -> 120 | G10: 0
B11: Persona 4 | C11: Propio | D11: 160 | E11: 0.75 | F11: =D11*E11 -> 120 | G11: 0
B12: Persona 5 | C12: Propio | D12: 160 | E12: 0.75 | F12: =D12*E12 -> 120 | G12: 0
B13: Persona 6 | C13: Propio | D13: 160 | E13: 0.75 | F13: =D13*E13 -> 120 | G13: 0
B14: Persona 7 | C14: Propio | D14: 160 | E14: 0.75 | F14: =D14*E14 -> 120 | G14: 0
B15: Persona 8 | C15: Propio | D15: 160 | E15: 0.75 | F15: =D15*E15 -> 120 | G15: 0
B17: TOTALES DEL EQUIPO | F17: =SUM(F8:F15) -> 960 | G17: =SUM(G8:G15) -> 0
B19: VALORES USADOS EN LAS CALCULADORAS
B20: Horas facturables totales/mes (equipo) | F20: =F17 -> 960 | G20: h/mes
B21: Coste total mensual del equipo (nóminas) | F21: =G17 -> 0 | G21: €/mes

Sheet 📚 Formaciones
B1: CALCULADORA DE PRECIOS — FORMACIONES
B4: A. COSTES DIRECTOS
B5: Personal propio (horas en este proyecto)
B6: Horas de trabajo propias | C6: 10 | D6: h
B7: Tarifa hora propia (referencia) | C7: 50 | D7: €/h
B8: Subtotal personal propio | D8: € | E8: =C6*C7 -> 500
B9: Colaboradores / Proveedores externos (hasta 5)
B10: Colaborador 1 — horas | C10: 0 | D10: h
B11: Colaborador 1 — tarifa/hora | C11: 0 | D11: €/h
B12: Subtotal colaborador 1 | E12: =C10*C11 -> 0
B13: Colaborador 2 — horas | C13: 0 | D13: h
B14: Colaborador 2 — tarifa/hora | C14: 0 | D14: €/h
B15: Subtotal colaborador 2 | E15: =C13*C14 -> 0
B16: Colaborador 3 — horas | C16: 0 | D16: h
B17: Colaborador 3 — tarifa/hora | C17: 0 | D17: €/h
B18: Subtotal colaborador 3 | E18: =C16*C17 -> 0
B19: Colaborador 4 — horas | C19: 0 | D19: h
B20: Colaborador 4 — tarifa/hora | C20: 0 | D20: €/h
B21: Subtotal colaborador 4 | E21: =C19*C20 -> 0
B22: Colaborador 5 — horas | C22: 0 | D22: h
B23: Colaborador 5 — tarifa/hora | C23: 0 | D23: €/h
B24: Subtotal colaborador 5 | E24: =C22*C23 -> 0
B25: Subtotal colaboradores (todos) | D25: € | E25: =E12+E15+E18+E21+E24 -> 0
B26: Otros costes directos
B27: Herramientas y software | C27: 0 | D27: €
B28: Materiales / entregables | C28: 0 | D28: €
B29: Desplazamientos y dietas | C29: 0 | D29: €
B30: Sala / plataforma de formación | C30: 0 | D30: €
B31: Materiales pedagógicos / manuales | C31: 0 | D31: €
B32: TOTAL COSTES DIRECTOS (A) | D32: € | E32: =E8+E25+E27+E28+E29+E30+E31 -> 500
B34: B. COSTES INDIRECTOS (estructura mensual prorrateada)
B35: Nóminas y costes de personal fijo (desde pestaña Equipo) | D35: €/mes | E35: ='👥 Equipo'!G17 -> 0
B36: Alquiler y suministros | C36: 0 | D36: €/mes
B37: Seguros | C37: 0 | D37: €/mes
B38: Cuota autónomos / costes societarios | C38: 0 | D38: €/mes
B39: Contabilidad y asesoría | C39: 0 | D39: €/mes
B40: Marketing y publicidad | C40: 0 | D40: €/mes
B41: Formación y desarrollo profesional | C41: 0 | D41: €/mes
B42: Herramientas de gestión | C42: 0 | D42: €/mes
B43: Total indirectos/mes (sin nóminas) | D43: € | E43: =SUM(C36:C42) -> 0
...

Sheet 🤝 Consultoría
B1: CALCULADORA DE PRECIOS — CONSULTORÍA
B4: A. COSTES DIRECTOS
B5: Personal propio (horas en este proyecto)
B6: Horas de trabajo propias | C6: 10 | D6: h
B7: Tarifa hora propia (referencia) | C7: 50 | D7: €/h
B8: Subtotal personal propio | D8: € | E8: =C6*C7 -> 500
B9: Colaboradores / Proveedores externos (hasta 5)
B10: Colaborador 1 — horas | C10: 0 | D10: h
B11: Colaborador 1 — tarifa/hora | C11: 0 | D11: €/h
B12: Subtotal colaborador 1 | E12: =C10*C11 -> 0
B13: Colaborador 2 — horas | C13: 0 | D13: h
B14: Colaborador 2 — tarifa/hora | C14: 0 | D14: €/h
B15: Subtotal colaborador 2 | E15: =C13*C14 -> 0
B16: Colaborador 3 — horas | C16: 0 | D16: h
B17: Colaborador 3 — tarifa/hora | C17: 0 | D17: €/h
B18: Subtotal colaborador 3 | E18: =C16*C17 -> 0
B19: Colaborador 4 — horas | C19: 0 | D19: h
B20: Colaborador 4 — tarifa/hora | C20: 0 | D20: €/h
B21: Subtotal colaborador 4 | E21: =C19*C20 -> 0
B22: Colaborador 5 — horas | C22: 0 | D22: h
B23: Colaborador 5 — tarifa/hora | C23: 0 | D23: €/h
B24: Subtotal colaborador 5 | E24: =C22*C23 -> 0
B25: Subtotal colaboradores (todos) | D25: € | E25: =E12+E15+E18+E21+E24 -> 0
B26: Otros costes directos
B27: Herramientas y software | C27: 0 | D27: €
B28: Materiales / entregables | C28: 0 | D28: €
B29: Desplazamientos y dietas | C29: 0 | D29: €
B30: Informes y documentación especializada | C30: 0 | D30: €
B31: Software de análisis / BI | C31: 0 | D31: €
B32: TOTAL COSTES DIRECTOS (A) | D32: € | E32: =E8+E25+E27+E28+E29+E30+E31 -> 500
B34: B. COSTES INDIRECTOS (estructura mensual prorrateada)
B35: Nóminas y costes de personal fijo (desde pestaña Equipo) | D35: €/mes | E35: ='👥 Equipo'!G17 -> 0
B36: Alquiler y suministros | C36: 0 | D36: €/mes
B37: Seguros | C37: 0 | D37: €/mes
B38: Cuota autónomos / costes societarios | C38: 0 | D38: €/mes
B39: Contabilidad y asesoría | C39: 0 | D39: €/mes
B40: Marketing y publicidad | C40: 0 | D40: €/mes
B41: Formación y desarrollo profesional | C41: 0 | D41: €/mes
B42: Herramientas de gestión | C42: 0 | D42: €/mes
B43: Total indirectos/mes (sin nóminas) | D43: € | E43: =SUM(C36:C42) -> 0
...

Sheet ⚙️ Ingeniería
B1: CALCULADORA DE PRECIOS — INGENIERÍA
B4: A. COSTES DIRECTOS
B5: Personal propio (horas en este proyecto)
B6: Horas de trabajo propias | C6: 10 | D6: h
B7: Tarifa hora propia (referencia) | C7: 50 | D7: €/h
B8: Subtotal personal propio | D8: € | E8: =C6*C7 -> 500
B9: Colaboradores / Proveedores externos (hasta 5)
B10: Colaborador 1 — horas | C10: 0 | D10: h
B11: Colaborador 1 — tarifa/hora | C11: 0 | D11: €/h
B12: Subtotal colaborador 1 | E12: =C10*C11 -> 0
B13: Colaborador 2 — horas | C13: 0 | D13: h
B14: Colaborador 2 — tarifa/hora | C14: 0 | D14: €/h
B15: Subtotal colaborador 2 | E15: =C13*C14 -> 0
B16: Colaborador 3 — horas | C16: 0 | D16: h
B17: Colaborador 3 — tarifa/hora | C17: 0 | D17: €/h
B18: Subtotal colaborador 3 | E18: =C16*C17 -> 0
B19: Colaborador 4 — horas | C19: 0 | D19: h
B20: Colaborador 4 — tarifa/hora | C20: 0 | D20: €/h
B21: Subtotal colaborador 4 | E21: =C19*C20 -> 0
B22: Colaborador 5 — horas | C22: 0 | D22: h
B23: Colaborador 5 — tarifa/hora | C23: 0 | D23: €/h
B24: Subtotal colaborador 5 | E24: =C22*C23 -> 0
B25: Subtotal colaboradores (todos) | D25: € | E25: =E12+E15+E18+E21+E24 -> 0
B26: Otros costes directos
B27: Herramientas y software | C27: 0 | D27: €
B28: Materiales / entregables | C28: 0 | D28: €
B29: Desplazamientos y dietas | C29: 0 | D29: €
B30: Licencias técnicas (CAD, BIM, etc.) | C30: 0 | D30: €
B31: Prototipado y pruebas | C31: 0 | D31: €
B32: Subcontratación especializada | C32: 0 | D32: €
B33: TOTAL COSTES DIRECTOS (A) | D33: € | E33: =E8+E25+E27+E28+E29+E30+E31+E32 -> 500
B35: B. COSTES INDIRECTOS (estructura mensual prorrateada)
B36: Nóminas y costes de personal fijo (desde pestaña Equipo) | D36: €/mes | E36: ='👥 Equipo'!G17 -> 0
B37: Alquiler y suministros | C37: 0 | D37: €/mes
B38: Seguros | C38: 0 | D38: €/mes
B39: Cuota autónomos / costes societarios | C39: 0 | D39: €/mes
B40: Contabilidad y asesoría | C40: 0 | D40: €/mes
B41: Marketing y publicidad | C41: 0 | D41: €/mes
B42: Formación y desarrollo profesional | C42: 0 | D42: €/mes
B43: Herramientas de gestión | C43: 0 | D43: €/mes
...

Sheet 📦 Producto
B1: CALCULADORA DE PRECIOS — PRODUCTO
B4: A. COSTE DE ADQUISICIÓN O FABRICACIÓN (por unidad)
B5: Materias primas | C5: 0 | D5: €/ud
B6: Producción / fabricación | C6: 0 | D6: €/ud
B7: Mano de obra directa | C7: 0 | D7: €/ud
B8: Empaquetado | C8: 0 | D8: €/ud
B9: Etiquetado | C9: 0 | D9: €/ud
B10: TOTAL FABRICACIÓN (A) | D10: € | E10: =SUM(C5:C9) -> 0
B12: B. COSTES LOGÍSTICOS (por unidad)
B13: Almacenamiento | C13: 0 | D13: €/ud
B14: Transporte | C14: 0 | D14: €/ud
B15: Envíos | C15: 0 | D15: €/ud
B16: Devoluciones (estimado) | C16: 0 | D16: €/ud
B17: TOTAL LOGÍSTICA (B) | D17: € | E17: =SUM(C13:C16) -> 0
B19: C. COSTES INDIRECTOS (prorrateo mensual)
B20: Marketing y publicidad | C20: 0 | D20: €/mes
B21: Personal | C21: 0 | D21: €/mes
B22: Software y herramientas | C22: 0 | D22: €/mes
B23: Administración y gestoría | C23: 0 | D23: €/mes
B24: Alquileres y suministros | C24: 0 | D24: €/mes
B25: Unidades vendidas al mes (estimado) | C25: 100 | D25: uds/mes
B26: Total indirectos/mes | D26: € | E26: =SUM(C20:C24) -> 0
B27: TOTAL INDIRECTOS POR UNIDAD (C) | D27: € | E27: =IF(C25=0,0,E26/C25) -> 0
B29: D. IMPUESTOS
B30: IVA/VAT (%) | C30: 0.21 | D30: %
B31: Aranceles (si procede) (%) | C31: 0 | D31: %
B33: COSTE TOTAL UNITARIO (A+B+C) | D33: € | E33: =E10+E17+E27 -> 0
B35: E. MARGEN COMERCIAL DESEADO
B36: Margen bruto objetivo (%) | C36: 0.4 | D36: %
B37: Margen neto objetivo (%) | C37: 0.2 | D37: %
B38: Fondo para reinversión (%) | C38: 0.05 | D38: %
B39: Margen total aplicado (%) | D39: % | E39: =C36+C38 -> 0.45
B40: PVP sin IVA (coste + margen) | D40: € | E40: =IF((1-E39)=0,0,E33/(1-E39)) -> 0
B42: F. VALOR PERCIBIDO
B43: Evalúa del 1 (bajo) al 5 (muy alto) cada atributo de valor del producto.
B44: Calidad percibida (1-5) | C44: 3 | D44: 1-5
B45: Marca y reputación (1-5) | C45: 3 | D45: 1-5
B46: Diseño y estética (1-5) | C46: 3 | D46: 1-5
B47: Exclusividad / escasez (1-5) | C47: 3 | D47: 1-5
B48: Conveniencia / facilidad (1-5) | C48: 3 | D48: 1-5
...

Sheet 📊 Resumen
B1: RESUMEN COMPARATIVO DE PRECIOS
B4: Introduce el precio sin IVA de cada pestaña en la columna azul. El IVA se aplica automáticamente.
B6: CATEGORÍA | C6: PRECIO SIN IVA (€) | D6: PRECIO CON IVA (€)
B7: 📚 Formaciones | C7: 0 | D7: =C7*(1+'🏠 Portada'!C10/100) -> 0
B8: 🤝 Consultoría | C8: 0 | D8: =C8*(1+'🏠 Portada'!C10/100) -> 0
B9: ⚙️ Ingeniería | C9: 0 | D9: =C9*(1+'🏠 Portada'!C10/100) -> 0
B10: 📦 Producto | C10: 0 | D10: =C10*(1+'🏠 Portada'!C10/100) -> 0
B12: ℹ️ Copia el precio sin IVA (celda E del precio recomendado) de cada pestaña aquí.
B14: COMPARATIVA RÁPIDA
B15: CATEGORÍA | C15: PRECIO s/IVA | D15: MAYOR PRECIO?
B16: 📚 Formaciones | C16: =C7 -> 0 | D16: =IF(C7=MAX($C$7:$C$10),"✅ Más alto","—") -> ✅ Más alto
B17: 🤝 Consultoría | C17: =C8 -> 0 | D17: =IF(C8=MAX($C$7:$C$10),"✅ Más alto","—") -> ✅ Más alto
B18: ⚙️ Ingeniería | C18: =C9 -> 0 | D18: =IF(C9=MAX($C$7:$C$10),"✅ Más alto","—") -> ✅ Más alto
B19: 📦 Producto | C19: =C10 -> 0 | D19: =IF(C10=MAX($C$7:$C$10),"✅ Más alto","—") -> ✅ Más alto
